Workbook

Sheet README
A1: Book A Sloth: India SEO Execution System
A2: Prepared 2026-10-10 for bookasloth.com. Market: India. Language: English (plus Hindi where noted).
A4: DATA SOURCES
A5: 1. Semrush 'Organic Positions' exports (India database) supplied by the user: calendly.com (359 rows, 2026-09-10), topmate.io (1,425 rows, 2026-09-10), setmore.com (2,216 rows, 2026-09-11). Volumes and KD in this workbook come only from these files.
A6: 2. Live India SERP checks (TinyFish search, location=IN, lang=en) for about 150 queries on 2026-10-10. A single non-personalised snapshot that approximates Google India; it does not capture the local pack, People Also Ask or AI Overviews.
A7: 3. Crawl of bookasloth.com sitemaps on 2026-10-10: 126 pages, 98 blog posts, 49 profession pages, 73 host profiles, 47 service pages.
A8: 4. Competitor site reviews (Zoho Bookings, Cal.com, Topmate, SuperProfile, TagMango, Exly, Graphy, Appointy, Setmore, SimplyBook, Instamojo, Razorpay, Practo) on 2026-10-10.
A10: WHAT IS NOT IN HERE
A11: No Google Search Console, GA4 or paid-tool access was available, so Book A Sloth's own impressions and rankings are unknown beyond the SERP checks (not in the top 20 for any of about 150 checked queries; about #13 for 'buffer time meaning').
A12: Keywords marked 'Unverified' have no volume or KD from any tool. They came from SERP research and forum phrasing. Validate them before treating any score as final.
A13: Competitor exports are top-N position lists, not full keyword universes. Calendly's India export covers only about 2k est. visits, so treat it as a sample.
A15: HOW TO READ THE SCORES
... A23: Blue text in the Scoring tab = editable inputs (weights, factor ratings).

Sheet Scoring
A1: Cluster scoring (weights are editable)
D2: Demand | E2: Feasibility | F2: Relevance | G2: Gap | H2: AI | I2: Sum (must be 100%)
A3: Weights → | D3: 0.25 | E3: 0.25 | F3: 0.25 | G3: 0.15 | H3: 0.1 | I3: =SUM(D3:H3)
A5: Cluster | B5: Name | C5: Pillar URL | D5: Demand (1-5) | E5: Feasibility (1-5) | F5: Relevance (1-5) | G5: Gap (1-5) | H5: AI (1-5) | I5: Score (0-100) | J5: Tier | K5: Data quality | L5: Evidence | M5: Product pages
A6: A | B6: India pricing, alternatives & comparisons | C6: /compare/best-appointment-booking-apps-india | D6: 3 | E6: 4 | F6: 5 | G6: 5 | H6: 5 | I6: =ROUND(($D$3*D6+$E$3*E6+$F$3*F6+$G$3*G6+$H$3*H6)/5*100,0) | J6: =IF(I6>=75,"Tier 1",IF(I6>=65,"Tier 2",IF(I6>=55,"Tier 3","Exclude"))) | K6: Provisional: few verified volumes; SERP evidence strong | L6: Every top-10 result for 'calendly pricing in india' quotes USD. 'topmate alternative' and 'calendly alternative india' top-10s are held by tiny .in startups (mintlink.in, ownstreet.in, zyncro.in, calenq.ai). Bottom-of-funnel and on-product. | M6: /pricing, /compare, /earnings-calculator, /features/payments
A7: B | B7: Getting paid: UPI, payment links, advance payments & GST | C7: /blog/collect-payments-from-clients-india | D7: 3 | E7: 3 | F7: 5 | G7: 4 | H7: 4 | I7: =ROUND(($D$3*D7+$E$3*E7+$F$3*F7+$G$3*G7+$H$3*H7)/5*100,0) | J7: =IF(I7>=75,"Tier 1",IF(I7>=65,"Tier 2",IF(I7>=55,"Tier 3","Exclude"))) | K7: Provisional: volumes unverified | L7: Calendly supports only Stripe/PayPal for paid events. Cal.com and Setmore users type UPI IDs into their booking pages by hand. 'Calendly razorpay integration' results are all connector pages. Razorpay's own blog covers payments but not booking. Book A Sloth's core differentiator. | M7: /features/payments, /tools/gst-calculator, /glossary/upi, /glossary/advance-payment
A8: C | B8: Client message templates (WhatsApp, SMS, Hindi) | C8: /templates | D8: 4 | E8: 4 | F8: 4 | G8: 5 | H8: 3 | I8: =ROUND(($D$3*D8+$E$3*E8+$F$3*F8+$G$3*G8+$H$3*H8)/5*100,0) | J8: =IF(I8>=75,"Tier 1",IF(I8>=65,"Tier 2",IF(I8>=55,"Tier 3","Exclude"))) | K8: Partly verified (Semrush IN) | L8: Copy-paste template pages win. Small and new Indian sites (meekhata.in, riffit.in, chatmitra, fastfee.in) rank top 10. Hindi template SERPs are filled with translate.google proxies of English pages. Setmore ranks #1-#7 for WhatsApp away-message terms at KD 12-20. | M8: /features/notifications, /glossary/whatsapp-reminder
A9: D | B9: No-shows, cancellations & booking policies | C9: /blog/how-to-reduce-no-shows | D9: 2 | E9: 3 | F9: 5 | G9: 4 | H9: 4 | I9: =ROUND(($D$3*D9+$E$3*E9+$F$3*F9+$G$3*G9+$H$3*H9)/5*100,0) | J9: =IF(I9>=75,"Tier 1",IF(I9>=65,"Tier 2",IF(I9>=55,"Tier 3","Exclude"))) | K9: Provisional: volumes unverified | L9: Policy-template SERPs include a real clinic's policy page and a Facebook post. No result gives ₹ examples or uses prepaid UPI to enforce the policy. The existing no-show cost calculator gives a tool hook. | M9: /tools/no-show-cost-calculator, /features/notifications, /features/payments, /glossary/no-show, /glossary/cancellation-policy
A10: E | B10: Interview & meeting message templates (traffic cluster) | C10: /blog/interview-calling-message | D10: 5 | E10: 4 | F10: 2 | G10: 3 | H10: 2 | I10: =ROUND(($D$3*D10+$E$3*E10+$F$3*F10+$G$3*G10+$H$3*H10)/5*100,0) | J10: =IF(I10>=75,"Tier 1",IF(I10>=65,"Tier 2",IF(I10>=55,"Tier 3","Exclude"))) | K10: Verified (Semrush IN, Sep 2026) | L10: Biggest verified demand: 110k/mo, KD 17-18. Calendly ranks only #29-34. The #1 result is a thin HRMS post, and a 1-day-old page is already ranking. Low buyer fit: HR recruiters are not the core ICP. Pages already exist, so the work is refresh only, not expansion. | M10: /features/booking-pages, /features/notifications
A11: F | B11: Scheduling concepts & glossary | C11: /glossary | D11: 4 | E11: 4 | F11: 3 | G11: 3 | H11: 5 | I11: =ROUND(($D$3*D11+$E$3*E11+$F$3*F11+$G$3*G11+$H$3*H11)/5*100,0) | J11: =IF(I11>=75,"Tier 1",IF(I11>=65,"Tier 2",IF(I11>=55,"Tier 3","Exclude"))) | K11: Verified (Semrush IN) | L11: Calendly's community and help pages rank for definitional queries (buffer time 1,300/KD20, placeholder meeting, 24/7 availability). /blog/scheduling-terms-glossary already sits at about #13 after 7 days. The 'please share anything that will help prepare for our meeting' SERP (2,400/KD21) is almost all forums and Q&A sites. Definitions are the most-cited format in AI answers. | M11: /features/availability, /features/google-calendar, /glossary/*
A12: G | B12: Start & grow an independent practice in India (playbooks + pricing guides) | C12: /blog/start-independent-practice-india | D12: 3 | E12: 3 | F12: 5 | G12: 4 | H12: 4 | I12: =ROUND(($D$3*D12+$E$3*E12+$F$3*F12+$G$3*G12+$H$3*H12)/5*100,0) | J12: =IF(I12>=75,"Tier 1",IF(I12>=65,"Tier 2",IF(I12>=55,"Tier 3","Exclude"))) | K12: Provisional: volumes unverified | L12: Practice-setup and pricing questions from Indian coaches, therapists, tutors and trainers. Book A Sloth can add original pricing data from its own bookings. Competitor guides are stale (Instamojo 2024, Exly 2021-23, Appointy 2023-24). | M12: /for/*, /be-a-sloth, /pricing, /earnings-calculator
A13: H | B13: Industry booking-software landing pages (/for/*) | C13: /appointment-booking-software | D13: 3 | E13: 2 | F13: 5 | G13: 3 | H13: 2 | I13: =ROUND(($D$3*D13+$E$3*E13+$F$3*F13+$G$3*G13+$H$3*H13)/5*100,0) | J13: =IF(I13>=75,"Tier 1",IF(I13>=65,"Tier 2",IF(I13>=55,"Tier 3","Exclude"))) | K13: Partly verified | L13: Head terms are held by Zoho, Setmore, Square and app stores, and many 'X app' queries are consumer intent. Winnable gaps: turf booking software (weak SERP), barber/makeup artist app (Setmore ranks at KD 19-20), therapists (no /for/ page yet), clinic booking software india (several small Indian sites). | M13: /for/*, /appointment-booking-software
A14: I | B14: Local marketplace pages (host profiles + profession × city) | C14: /services | D14: 4 | E14: 3 | F14: 4 | G14: 3 | H14: 1 | I14: =ROUND(($D$3*D14+$E$3*E14+$F$3*F14+$G$3*G14+$H$3*H14)/5*100,0) | J14: =IF(I14>=75,"Tier 1",IF(I14>=65,"Tier 2",IF(I14>=55,"Tier 3","Exclude"))) | K14: Verified examples (Semrush IN) + live SERP checks | L14: 100 local keywords (37,450/mo combined) where Setmore customer pages and Topmate profiles rank at median KD 15-30. Live check: amritaspa.setmore.com is #3 for 'spa in malviya nagar'. therapyroute ranks #5 for 'therapist in nagpur' with only 6 listings. Only worth doing where real host supply exists. | M14: /explore, /services/{profession}, host profiles
A15: L | B15: Booking-link how-tos (Instagram, Google, website) | C15: /blog/booking-link-instagram-bio | D15: 3 | E15: 3 | F15: 5 | G15: 3 | H15: 3 | I15: =ROUND(($D$3*D15+$E$3*E15+$F$3*F15+$G$3*G15+$H$3*H15)/5*100,0) | J15: =IF(I15>=75,"Tier 1",IF(I15>=65,"Tier 2",IF(I15>=55,"Tier 3","Exclude"))) | K15: Partly verified | L15: 'booking link for instagram' is ranked by how-to posts from Reservio (Jun 2026) and lovingbooking (Jul 2026), with no India version. Setmore ranks #3 for 'booking button' (210/KD23) with a Google Business Profile post. | M15: /features/booking-pages, /features/google-calendar
A16: K | B16: Expert & creator monetisation | C16: /blog/how-to-make-money-from-home-india | D16: 3 | E16: 3 | F16: 3 | G16: 2 | H16: 2 | I16: =ROUND(($D$3*D16+$E$3*E16+$F$3*F16+$G$3*G16+$H$3*H16)/5*100,0) | J16: =IF(I16>=75,"Tier 1",IF(I16>=65,"Tier 2",IF(I16>=55,"Tier 3","Exclude"))) | K16: Verified (Semrush IN) | L16: Topmate's homepage ranks #1 for 'how to make money from home in india' (480/KD14). Most of Topmate's blog traffic is Instagram-growth content with no buyer value. Keep the existing posts fresh; don't expand. | M16: /be-a-sloth, /features/digital-products
A17: X | B17: Excluded themes | D17: 2 | E17: 2 | F17: 1 | G17: 1 | H17: 1 | I17: =ROUND(($D$3*D17+$E$3*E17+$F$3*F17+$G$3*G17+$H$3*H17)/5*100,0) | J17: =IF(I17>=75,"Tier 1",IF(I17>=65,"Tier 2",IF(I17>=55,"Tier 3","Exclude"))) | K17: n/a | L17: Instagram follower/likes growth (Topmate's top 25k visits), HR onboarding welcome messages, student planners, Salesforce/sales ops, vaccine slots, dental/coaching ERP head terms, lawyer/CA city pages, 'superprofile alternative' (searchers want Instagram DM automation), off-ICP 'digital marketing for X' posts.
A19: Score formula: ROUND(Σ weight × factor ÷ 5 × 100). The same formula scores every page in the Article Plan tab, using these weight cells.

Sheet Article Plan
A1: Publish order | B1: First 30? | C1: Week | D1: ID | E1: Cluster | F1: Role | G1: Action | H1: Title | I1: Recommended URL | J1: Primary keyword | K1: Volume (IN) | L1: KD | M1: Supporting keywords | N1: Intent | O1: Funnel | P1: Demand | Q1: Feasibility | R1: Relevance | S1: Gap | T1: AI | U1: Score | V1: Tier | W1: Decision | X1: Angle / how it differs | Y1: SERP evidence (2026-10-10) | Z1: Product page | AA1: Links to | AB1: Research / assets
A2: 1 | B2: Yes | C2: 1 | D2: A2 | E2: A: India pricing, alternatives & comparisons | F2: Support | G2: New | H2: Calendly Pricing in India (2026): Plans in ₹, GST, Card Forex & the Free Plan Limits | I2: /compare/calendly-pricing-india | J2: calendly pricing in india | K2: Unverified | L2: n/a | M2: is calendly free, calendly free plan limits, calendly price in rupees, calendly razorpay | N2: Commercial | O2: Consideration | P2: 3 | Q2: 4 | R2: 5 | S2: 5 | T2: 5 | U2: =ROUND((Scoring!$D$3*P2+Scoring!$E$3*Q2+Scoring!$F$3*R2+Scoring!$G$3*S2+Scoring!$H$3*T2)/5*100,0) | V2: =IF(U2>=75,"Tier 1",IF(U2>=65,"Tier 2",IF(U2>=55,"Tier 3","Exclude"))) | W2: Publish now | X2: The only page that answers in INR: each USD plan converted at a dated rate, plus 18% GST (reverse charge for businesses), plus the ~3.5% card forex markup. Explains that Calendly takes payments only via Stripe/PayPal, so it has no UPI. Ends with a total-cost table. | Y2: All 10 results quote USD: calendly ×3, zoho, koalendar, withorb, cloudeagle, capterra.in, zeeg, tidycal. | Z2: /pricing, /earnings-calculator | AA2: A3, A1, A9, /pricing | AB2: Calendly pricing screenshot, RBI reference rate with date, a card forex markup source
A3: 2 | B3: Yes | C3: 1 | D3: C1 | E3: C: Client message templates (WhatsApp, SMS, Hindi) | F3: Support | G3: Refresh | H3: WhatsApp Appointment Reminder Templates: 30+ Messages for Clinics, Salons, Tutors & Coaches (English + Hindi) | I3: /blog/appointment-reminder-templates | J3: whatsapp reminder message for appointment | K3: Unverified | L3: n/a | M3: appointment reminder message, whatsapp reminder, doctor appointment message, salon appointment reminder message, daily text reminders | N3: Informational | O3: Consideration | P3: 4 | Q3: 3 | R3: 5 | S3: 4 | T3: 3 | U3: =ROUND((Scoring!$D$3*P3+Scoring!$E$3*Q3+Scoring!$F$3*R3+Scoring!$G$3*S3+Scoring!$H$3*T3)/5*100,0) | V3: =IF(U3>=75,"Tier 1",IF(U3>=65,"Tier 2",IF(U3>=55,"Tier 3","Exclude"))) | W3: Publish now | X3: Go from about 10 to 30+ templates: per-trade sets (doctor with token/OPD timing, salon festive and bridal, tutor, coach), Hindi, a reminder-timing table, and a workflow for the free WhatsApp Business app vs automation. | Y3: chati.ai (#1, about 900 words, 30 one-liners), wati and aisensy rank. Calendly community is #9 for 'whatsapp reminder' (590/KD24). Book A Sloth is not in the top 20. | Z3: /features/notifications | AA3: C0, C2, D1, /glossary/whatsapp-reminder, /features/notifications | AB3: Hindi copy check by a native speaker
A4: 3 | B4: Yes | C4: 1 | D4: C0 | E4: C: Client message templates (WhatsApp, SMS, Hindi) | F4: Pillar | G4: New | H4: Free Message Templates for Service Businesses in India (WhatsApp, SMS, Email, Hindi) | I4: /templates | J4: whatsapp message templates for business | K4: Unverified | L4: n/a | M4: business message templates, client message templates, whatsapp templates for clinic | N4: Informational | O4: Awareness | P4: 3 | Q4: 3 | R4: 4 | S4: 4 | T4: 3 | U4: =ROUND((Scoring!$D$3*P4+Scoring!$E$3*Q4+Scoring!$F$3*R4+Scoring!$G$3*S4+Scoring!$H$3*T4)/5*100,0) | V4: =IF(U4>=75,"Tier 1",IF(U4>=65,"Tier 2",IF(U4>=55,"Tier 3","Exclude"))) | W4: Publish now | X4: A hub that indexes every template page by job (confirm, remind, reschedule, cancel, get paid, thank, review) and by profession. No URL moves: existing /blog template posts stay where they are. | Y4: Hub page. It earns rankings mainly through internal links. | Z4: /features/notifications | AA4: C1, C2, C3, C4, C5, C6, C7, C8, C12, B6, E1, E3 | AB4: Hub design
A5: 4 | B5: Yes | C5: 2 | D5: A3 | E5: A: India pricing, alternatives & comparisons | F5: Comparison | G5: Consolidate | H5: Calendly Alternative for India: Get Booked and Paid via UPI (Migration Guide) | I5: /compare/calendly-alternative-india | J5: calendly alternative india | K5: Unverified | L5: n/a | M5: calendly alternative, calendly alternatives free, free calendly alternative, calendly upi | N5: Commercial | O5: Conversion | P5: 3 | Q5: 4 | R5: 5 | S5: 4 | T5: 4 | U5: =ROUND((Scoring!$D$3*P5+Scoring!$E$3*Q5+Scoring!$F$3*R5+Scoring!$G$3*S5+Scoring!$H$3*T5)/5*100,0) | V5: =IF(U5>=75,"Tier 1",IF(U5>=65,"Tier 2",IF(U5>=55,"Tier 3","Exclude"))) | W5: Publish now | X5: Merge /lp/calendly-alternative into this page. Add proof the identical 'UPI+GST' competitor pages lack: a feature matrix, a 5-step migration walkthrough with screenshots, ₹ cost maths, and a dated 'last updated'. | Y5: zoho, capterra.in, zyncro.in, swiq.services, calenq.ai and bookyourcalendar.com rank: tiny Indian startups with exact-match pages. Reddit is #5 for the global 'calendly alternative'. | Z5: /features/payments, /pricing | AA5: A2, A1, B1, /pricing | AB5: Migration screenshots; a 301 or noindex decision for the /lp page
A6: 5 | B6: Yes | C6: 2 | D6: A9 | E6: A: India pricing, alternatives & comparisons | F6: Support | G6: New | H6: Can You Take UPI Payments on Calendly? (And 3 Workarounds Indian Professionals Use) | I6: /blog/calendly-upi-payments | J6: calendly upi payment | K6: Unverified | L6: n/a | M6: calendly razorpay integration, calendly paid events india, calendly payment india | N6: Informational | O6: Consideration | P6: 2 | Q6: 4 | R6: 5 | S6: 5 | T6: 5 | U6: =ROUND((Scoring!$D$3*P6+Scoring!$E$3*Q6+Scoring!$F$3*R6+Scoring!$G$3*S6+Scoring!$H$3*T6)/5*100,0) | V6: =IF(U6>=75,"Tier 1",IF(U6>=65,"Tier 2",IF(U6>=55,"Tier 3","Exclude"))) | W6: Publish now | X6: Answer first: not natively (Stripe/PayPal only). Then compare the Zapier/Pabbly/Integrately connectors with a manual UPI-ID workflow and a native-UPI booking tool, covering cost, failure points and refunds. | Y6: 'calendly razorpay integration' returns only connector pages (Zoho Flow, Integrately, Pabbly, Zapier, Albato) plus a dev.to post on 'the Razorpay gap'. | Z6: /features/payments | AA6: A2, A3, B1, B2 | AB6: Test a Zapier flow; screenshots
A7: 6 | B7: Yes | C7: 2 | D7: F1 | E7: F: Scheduling concepts & glossary | F7: Pillar | G7: Consolidate | H7: Scheduling Glossary: 40+ Booking Terms Explained (with Indian Examples) | I7: /glossary | J7: buffer time meaning | K7: 1300 | L7: 20 | M7: buffer day, placeholder meeting meaning, 24 7 availability, lead time meaning, scheduling terms | N7: Informational | O7: Awareness | P7: 4 | Q7: 4 | R7: 3 | S7: 3 | T7: 5 | U7: =ROUND((Scoring!$D$3*P7+Scoring!$E$3*Q7+Scoring!$F$3*R7+Scoring!$G$3*S7+Scoring!$H$3*T7)/5*100,0) | V7: =IF(U7>=75,"Tier 1",IF(U7>=65,"Tier 2",IF(U7>=55,"Tier 3","Exclude"))) | W7: Publish now | X7: Make /glossary the single home for definitions. 301 /blog/scheduling-terms-glossary into /glossary/buffer-time, carrying its content. Expand every entry to 250-500 words with a 1-sentence answer box, an example and a 'related terms' block, and add DefinedTerm schema. | Y7: /blog/scheduling-terms-glossary is about #13 for 'buffer time meaning' (1,300/KD20). Calendly help ranks #18. | Z7: /features/availability | AA7: F4, D3, /features/availability | AB7: 301 map; schema
A8: 7 | B8: Yes | C8: 3 | D8: F2 | E8: F: Scheduling concepts & glossary | F8: Support | G8: New | H8: 'Please Share Anything That Will Help Prepare for Our Meeting': What to Write (30 Examples) | I8: /blog/please-share-anything-that-will-help-prepare-for-our-meeting | J8: please share anything that will help prepare for our meeting | K8: 2400 | L8: 21 | M8: what to write in meeting notes before call, booking form notes examples, what to write when booking a consultation | N8: Informational | O8: Awareness | P8: 4 | Q8: 5 | R8: 3 | S8: 5 | T8: 4 | U8: =ROUND((Scoring!$D$3*P8+Scoring!$E$3*Q8+Scoring!$F$3*R8+Scoring!$G$3*S8+Scoring!$H$3*T8)/5*100,0) | V8: =IF(U8>=75,"Tier 1",IF(U8>=65,"Tier 2",IF(U8>=55,"Tier 3","Exclude"))) | W8: Publish now | X8: Example answers by situation (job interview, sales demo, therapy intake, consultant call). Then flip to the host side: which intake questions to ask instead. | Y8: Almost all forums and Q&A (reddit r/recruiting, community.calendly, brainly, chegg). Calendly community ranks #3 (2,400/KD21). | Z8: /glossary/intake-form, /features/booking-pages | AA8: F3, C7, /glossary/intake-form
A9: 8 | B9: Yes | C9: 3 | D9: A4 | E9: A: India pricing, alternatives & comparisons | F9: Support | G9: New | H9: Topmate Commission & Fees Explained (2026): What You Actually Keep per ₹1,000 | I9: /compare/topmate-commission | J9: topmate commission | K9: Unverified | L9: n/a | M9: topmate charges, topmate pricing, topmate fees, topmate payout | N9: Commercial | O9: Consideration | P9: 2 | Q9: 4 | R9: 5 | S9: 5 | T9: 5 | U9: =ROUND((Scoring!$D$3*P9+Scoring!$E$3*Q9+Scoring!$F$3*R9+Scoring!$G$3*S9+Scoring!$H$3*T9)/5*100,0) | V9: =IF(U9>=75,"Tier 1",IF(U9>=65,"Tier 2",IF(U9>=55,"Tier 3","Exclude"))) | W9: Publish now | X9: A worked example: 10% own-link and 20% marketplace fee (per topmate.io), plus the payment gateway fee, plus GST on the fee. Embeds a calculator (see A11). Factual and neutral, with sources. | Y9: The top 10 includes topmate's own pages, linkedin, an eximpe blog, medium, reddit and swadeshiapps. Small explainer sites rank. | Z9: /earnings-calculator, /pricing | AA9: A5, A11, /glossary/commission, /glossary/platform-fee | AB9: Topmate pricing page capture (dated); calculator
A10: 9 | B10: Yes | C10: 3 | D10: A11 | E10: A: India pricing, alternatives & comparisons | F10: Tool | G10: Refresh | H10: Booking Platform Fee Calculator (Topmate, Calendly, SuperProfile, Book A Sloth) | I10: /earnings-calculator | J10: booking platform fee calculator | K10: Unverified | L10: n/a | M10: topmate fee calculator, commission calculator for creators | N10: Commercial | O10: Consideration | P10: 2 | Q10: 4 | R10: 5 | S10: 4 | T10: 4 | U10: =ROUND((Scoring!$D$3*P10+Scoring!$E$3*Q10+Scoring!$F$3*R10+Scoring!$G$3*S10+Scoring!$H$3*T10)/5*100,0) | V10: =IF(U10>=75,"Tier 1",IF(U10>=65,"Tier 2",IF(U10>=55,"Tier 3","Exclude"))) | W10: Publish now | X10: Extend the existing /earnings-calculator to compare platforms side by side, and link it from A2, A4 and A5. A calculator is a citable, linkable asset. | Y10: No calculator ranks for these fee queries. | Z10: /pricing | AA10: A4, A5, A2 | AB10: Dev work: fee inputs per platform with dated sources
A11: 10 | B11: Yes | C11: 3 | D11: F4 | E11: F: Scheduling concepts & glossary | F11: Glossary | G11: New | H11: New glossary entries: placeholder meeting, recurring meeting, soft booking, direct booking, preferred time, 24/7 availability, internal vs external meeting | I11: /glossary/{term} | J11: placeholder meeting | K11: 170 | L11: 20 | M11: placeholder meeting meaning, recurring meeting, soft booking, direct booking, preferred time, internal meeting | N11: Informational | O11: Awareness | P11: 3 | Q11: 4 | R11: 3 | S11: 3 | T11: 5 | U11: =ROUND((Scoring!$D$3*P11+Scoring!$E$3*Q11+Scoring!$F$3*R11+Scoring!$G$3*S11+Scoring!$H$3*T11)/5*100,0) | V11: =IF(U11>=75,"Tier 1",IF(U11>=65,"Tier 2",IF(U11>=55,"Tier 3","Exclude"))) | W11: Publish now | X11: Short definitional entries, each targeting a verified low-KD term, all under /glossary. One URL per term, no blog duplicates. | Y11: Calendly community and help pages rank for these (placeholder 390/KD24, recurring 210/KD19, soft booking 210/KD16, direct booking 210/KD20). | Z11: /features/availability | AA11: F1
A12: 11 | B12: Yes | C12: 4 | D12: A5 | E12: A: India pricing, alternatives & comparisons | F12: Comparison | G12: Consolidate | H12: Topmate Alternative for Consultants, Therapists & Coaches (0% Commission) | I12: /compare/topmate-alternative | J12: topmate alternative | K12: Unverified | L12: n/a | M12: topmate alternatives, topmate vs book a sloth, topmate competitors | N12: Commercial | O12: Conversion | P12: 3 | Q12: 4 | R12: 5 | S12: 4 | T12: 4 | U12: =ROUND((Scoring!$D$3*P12+Scoring!$E$3*Q12+Scoring!$F$3*R12+Scoring!$G$3*S12+Scoring!$H$3*T12)/5*100,0) | V12: =IF(U12>=75,"Tier 1",IF(U12>=65,"Tier 2",IF(U12>=55,"Tier 3","Exclude"))) | W12: Publish now | X12: 301 /blog/topmate-alternative and /lp/topmate-vs-bookasloth here. Aim it at professionals (therapists, consultants) rather than creators. Include a ₹ fee comparison and a profile-migration walkthrough. | Y12: adplist, mintlink.in (19 Aug 2026), an x.com tweet, virtup, ownstreet.in and kreato.co.in rank. Tiny Indian sites dominate. | Z12: /pricing, /features/booking-pages | AA12: A4, A10, A1, /earnings-calculator | AB12: Fee comparison table; 301 map
A13: 12 | B13: Yes | C13: 4 | D13: B1 | E13: B: Getting paid: UPI, payment links, advance payments & GST | F13: Pillar | G13: New | H13: How to Collect Payments from Clients in India: UPI, Payment Links & Advance Booking (2026 Guide) | I13: /blog/collect-payments-from-clients-india | J13: how to collect payment from clients online india | K13: Unverified | L13: n/a | M13: how to accept upi payments for business, payment link for freelancers, how to take online consultation fees, accept payment without website | N13: Informational | O13: Consideration | P13: 3 | Q13: 4 | R13: 5 | S13: 4 | T13: 4 | U13: =ROUND((Scoring!$D$3*P13+Scoring!$E$3*Q13+Scoring!$F$3*R13+Scoring!$G$3*S13+Scoring!$H$3*T13)/5*100,0) | V13: =IF(U13>=75,"Tier 1",IF(U13>=65,"Tier 2",IF(U13>=55,"Tier 3","Exclude"))) | W13: Publish now | X13: Compares UPI ID/QR, payment links, gateway checkout and pay-at-booking on fees, auto-confirmation, refunds and GST invoices. Includes a decision table by profession. Razorpay's blog covers payment links but never booking. | Y13: Fintech blogs (Razorpay, Cashfree, Instamojo) and Quora threads rank. Instamojo titles still say 2024. | Z13: /features/payments | AA13: B2, B3, B4, B6, A9, /glossary/upi, /glossary/payment-gateway | AB13: Fee table with sources (Razorpay, Cashfree, PhonePe PG); screenshots of the Book A Sloth pay-at-booking flow
A14: 13 | B14: Yes | C14: 4 | D14: B6 | E14: B: Getting paid: UPI, payment links, advance payments & GST | F14: Support | G14: Refresh | H14: How to Ask a Client for Payment Politely (Email, WhatsApp & Call Scripts) | I14: /blog/how-to-ask-client-for-payment-politely | J14: how to ask client for payment | K14: 720 | L14: 15 | M14: how to ask client for payment politely, payment follow up email, polite payment reminder email | N14: Informational | O14: Awareness | P14: 3 | Q14: 3 | R14: 4 | S14: 3 | T14: 3 | U14: =ROUND((Scoring!$D$3*P14+Scoring!$E$3*Q14+Scoring!$F$3*R14+Scoring!$G$3*S14+Scoring!$H$3*T14)/5*100,0) | V14: =IF(U14>=75,"Tier 1",IF(U14>=65,"Tier 2",IF(U14>=55,"Tier 3","Exclude"))) | W14: Publish now | X14: Add a phone script, a 'pause work' template and the MSME Act 45-day payment rule. It is already the only India-specific result. | Y14: #1 is neat.com (2022, US). Calendly community ranks #15 for 'how to ask client for payment' (720/KD15). Book A Sloth is not in the top 20. | Z14: /features/payments | AA14: C4, B1, B2 | AB14: MSME Act section reference
A15: 14 | B15: Yes | C15: 5 | D15: C4 | E15: C: Client message templates (WhatsApp, SMS, Hindi) | F15: Support | G15: New | H15: Payment Reminder Messages for Clients: WhatsApp & Email Templates (Polite to Firm) | I15: /blog/payment-reminder-message | J15: payment reminder message | K15: Unverified | L15: n/a | M15: payment reminder message for client, payment due reminder whatsapp, overdue payment message | N15: Informational | O15: Consideration | P15: 3 | Q15: 4 | R15: 5 | S15: 4 | T15: 3 | U15: =ROUND((Scoring!$D$3*P15+Scoring!$E$3*Q15+Scoring!$F$3*R15+Scoring!$G$3*S15+Scoring!$H$3*T15)/5*100,0) | V15: =IF(U15>=75,"Tier 1",IF(U15>=65,"Tier 2",IF(U15>=55,"Tier 3","Exclude"))) | W15: Publish now | X15: Sequenced templates (before due, due day, +3, +7, final), each with a UPI link line. Separate from B6 because its SERP is template pages, not how-to guides. | Y15: meekhata.in (small Indian site) is #1 and riffit.in #6. | Z15: /features/payments | AA15: B6, C5, C12, B1
A16: 15 | B16: Yes | C16: 5 | D16: C13 | E16: C: Client message templates (WhatsApp, SMS, Hindi) | F16: Sub-pillar | G16: New | H16: How to Manage Appointments on WhatsApp (and When a Booking Link Saves You Hours) | I16: /blog/manage-appointments-on-whatsapp | J16: how to manage appointments on whatsapp | K16: Unverified | L16: n/a | M16: whatsapp appointment booking, online booking vs whatsapp booking, whatsapp booking system for clinic, whatsapp business for doctors, does whatsapp have appointment booking | N16: Informational | O16: Consideration | P16: 3 | Q16: 3 | R16: 5 | S16: 5 | T16: 4 | U16: =ROUND((Scoring!$D$3*P16+Scoring!$E$3*Q16+Scoring!$F$3*R16+Scoring!$G$3*S16+Scoring!$H$3*T16)/5*100,0) | V16: =IF(U16>=75,"Tier 1",IF(U16>=65,"Tier 2",IF(U16>=55,"Tier 3","Exclude"))) | W16: Publish now | X16: An honest comparison of manual WhatsApp, a WhatsApp API bot and a booking link plus WhatsApp reminders, with time and no-show costs. Includes the hidden costs of the WhatsApp Business API (per-conversation pricing). | Y16: WhatsApp API vendors dominate (infobip, gallabox, aisensy, respond.io). A Reddit r/indianstartups thread on WhatsApp scheduling ranks #5. | Z16: /features/notifications, /features/booking-pages | AA16: C1, C6, D1, A1 | AB16: Book A Sloth host interview or case study
A17: 16 | B17: Yes | C17: 5 | D17: E1 | E17: E: Interview & meeting message templates (traffic cluster) | F17: Pillar | G17: Refresh | H17: Interview Calling Message: 25+ Templates (WhatsApp, SMS, Email, Hindi) | I17: /blog/interview-calling-message | J17: interview calling message | K17: 110000 | L17: 18 | M17: interview call message, interview invitation message, message for interview call, interview invitation sms, interview mail format, invitation for interview text message | N17: Informational | O17: Awareness | P17: 5 | Q17: 4 | R17: 2 | S17: 3 | T17: 2 | U17: =ROUND((Scoring!$D$3*P17+Scoring!$E$3*Q17+Scoring!$F$3*R17+Scoring!$G$3*S17+Scoring!$H$3*T17)/5*100,0) | V17: =IF(U17>=75,"Tier 1",IF(U17>=65,"Tier 2",IF(U17>=55,"Tier 3","Exclude"))) | W17: Publish now | X17: Add a Hindi/Hinglish WhatsApp version, a walk-in template with a documents list (Aadhaar, photos), a reminder template, and a 'book your slot' link template that shows the product in use. | Y17: savvyhrms (#1, thin), in.indeed, homerun and hyring rank; prajjo.com is 1 day old. Calendly ranks #29-34. Book A Sloth is not in the top 20. | Z17: /features/booking-pages | AA17: E2, E5, C1
A18: 17 | B18: Yes | C18: 6 | D18: G1 | E18: G: Start & grow an independent practice in India (playbooks + pricing guides) | F18: Pillar | G18: New | H18: How Much to Charge for a Consultation in India (2026): ₹ Rates by Profession | I18: /blog/consultation-fees-india | J18: how much to charge for consultation india | K18: Unverified | L18: n/a | M18: consultation charges in india, online consultation fees, how much to charge per hour consultant india, consultation fee kitna lena chahiye | N18: Informational | O18: Consideration | P18: 3 | Q18: 5 | R18: 5 | S18: 5 | T18: 5 | U18: =ROUND((Scoring!$D$3*P18+Scoring!$E$3*Q18+Scoring!$F$3*R18+Scoring!$G$3*S18+Scoring!$H$3*T18)/5*100,0) | V18: =IF(U18>=75,"Tier 1",IF(U18>=65,"Tier 2",IF(U18>=55,"Tier 3","Exclude"))) | W18: Publish now | X18: Original research: the median listed price per profession on Book A Sloth plus a small host survey, shown with ranges, sample sizes and the date. This is the cluster's most citable asset (an India Service Pricing Index). Refresh every quarter. | Y18: Dominated by UGC: Facebook ×2, Instagram, Reddit ×2, Quora ×2. Rated High feasibility. | Z18: /pricing, /earnings-calculator | AA18: G3, G6, G8, G9, G4c, A11 | AB18: Book A Sloth listings data export (n by profession; publish only professions with n≥20)
A19: 18 | B19: Yes | C19: 6 | D19: G3 | E19: G: Start & grow an independent practice in India (playbooks + pricing guides) | F19: Support | G19: New | H19: How Much Should a Personal Trainer Charge in India? Session, Monthly & Online Rate Card | I19: /blog/personal-trainer-charges-india | J19: how much do personal trainers charge in india | K19: Unverified | L19: n/a | M19: personal trainer fees per month india, online personal trainer charges, personal trainer price per session delhi | N19: Informational | O19: Consideration | P19: 2 | Q19: 5 | R19: 5 | S19: 5 | T19: 4 | U19: =ROUND((Scoring!$D$3*P19+Scoring!$E$3*Q19+Scoring!$F$3*R19+Scoring!$G$3*S19+Scoring!$H$3*T19)/5*100,0) | V19: =IF(U19>=75,"Tier 1",IF(U19>=65,"Tier 2",IF(U19>=55,"Tier 3","Exclude"))) | W19: Publish now | X19: The trainer's side of a query dominated by client-side Reddit and Quora answers. City tiers, package maths and UPI subscriptions. | Y19: Reddit ×2 and Quora ×3 dominate. Rated High feasibility. | Z19: /for/fitness | AA19: G1, /blog/how-to-become-freelance-personal-trainer, /for/fitness | AB19: Book A Sloth trainer price data
A20: 19 | B20: Yes | C20: 6 | D20: C6 | E20: C: Client message templates (WhatsApp, SMS, Hindi) | F20: Support | G20: New | H20: WhatsApp Business Away Message: 40 Templates + How to Set It Up (Holidays, After-Hours, Busy) | I20: /blog/whatsapp-business-away-message | J20: away message for business | K20: 480 | L20: 12 | M20: away message whatsapp, best away message for whatsapp business, away message for business whatsapp, away from whatsapp, whatsapp business away message | N20: Informational | O20: Awareness | P20: 3 | Q20: 4 | R20: 4 | S20: 4 | T20: 3 | U20: =ROUND((Scoring!$D$3*P20+Scoring!$E$3*Q20+Scoring!$F$3*R20+Scoring!$G$3*S20+Scoring!$H$3*T20)/5*100,0) | V20: =IF(U20>=75,"Tier 1",IF(U20>=65,"Tier 2",IF(U20>=55,"Tier 3","Exclude"))) | W20: Publish now | X20: Setup steps plus templates by trade and by Indian holiday (Diwali, Sunday closed), each ending with a booking link so the away message keeps taking bookings. | Y20: faq.whatsapp, getkanal, kommunicate and trengo rank. Setmore's blog ranks #1 for 'away message whatsapp' (320/KD20) and #7 for 'away message for business' (480/KD12). | Z20: /features/booking-pages | AA20: C13, C0, L1 | AB20: Setup screenshots
A21: 20 | B21: Yes | C21: 7 | D21: B2 | E21: B: Getting paid: UPI, payment links, advance payments & GST | F21: Support | G21: New | H21: How to Take Advance Payment for Appointments (Without Chasing UPI Screenshots) | I21: /blog/advance-payment-for-appointments | J21: advance payment for appointment | K21: Unverified | L21: n/a | M21: booking deposit, prepaid appointments, advance booking payment, how to take booking amount | N21: Informational | O21: Consideration | P21: 2 | Q21: 4 | R21: 5 | S21: 5 | T21: 4 | U21: =ROUND((Scoring!$D$3*P21+Scoring!$E$3*Q21+Scoring!$F$3*R21+Scoring!$G$3*S21+Scoring!$H$3*T21)/5*100,0) | V21: =IF(U21>=75,"Tier 1",IF(U21>=65,"Tier 2",IF(U21>=55,"Tier 3","Exclude"))) | W21: Publish now | X21: Covers deposit vs full prepay, how much to charge by profession, policy wording and refunds. Link to the build-in-public story /blog/advance-payments-without-the-screenshot-dance as first-hand proof. | Y21: Not checked; no strong ranking page was observed for related queries. | Z21: /features/payments | AA21: B1, D2, D1, /glossary/advance-payment | AB21: Book A Sloth data: no-show rate prepaid vs unpaid (if sample allows)
A22: 21 | B22: Yes | C22: 7 | D22: D2 | E22: D: No-shows, cancellations & booking policies | F22: Template | G22: New | H22: Cancellation & No-Show Policy Templates for Appointments (₹ Examples for Clinics, Coaches & Salons) | I22: /templates/cancellation-policy | J22: cancellation policy for appointments | K22: Unverified | L22: n/a | M22: no show policy template, late cancellation fee, cancellation policy template, refund policy for coaching | N22: Informational | O22: Consideration | P22: 2 | Q22: 4 | R22: 5 | S22: 4 | T22: 4 | U22: =ROUND((Scoring!$D$3*P22+Scoring!$E$3*Q22+Scoring!$F$3*R22+Scoring!$G$3*S22+Scoring!$H$3*T22)/5*100,0) | V22: =IF(U22>=75,"Tier 1",IF(U22>=65,"Tier 2",IF(U22>=55,"Tier 3","Exclude"))) | W22: Publish now | X22: One page for both SERPs (no-show and cancellation policy results overlap: koalendar, acuity and appointmentreminder rank for both). Copy-ready policies with ₹ fees, per-trade versions, and how prepaid UPI enforces them. | Y22: trilife.in (a real Indian clinic policy page) and a Facebook post rank. thebadtherapist.coach ranks for 'no show policy template'. | Z22: /features/payments | AA22: D1, B2, C3, /glossary/cancellation-policy | AB22: Consumer-law note for refunds
A23: 22 | B23: Yes | C23: 7 | D23: C3 | E23: C: Client message templates (WhatsApp, SMS, Hindi) | F23: Support | G23: New | H23: Appointment Cancellation & Reschedule Messages: Templates for Businesses and Clients | I23: /blog/appointment-cancellation-reschedule-message | J23: appointment cancellation message | K23: Unverified | L23: n/a | M23: reschedule meeting message, reschedule appointment, cancel appointment, rebook appointment, reschedule meeting | N23: Informational | O23: Consideration | P23: 3 | Q23: 4 | R23: 5 | S23: 4 | T23: 3 | U23: =ROUND((Scoring!$D$3*P23+Scoring!$E$3*Q23+Scoring!$F$3*R23+Scoring!$G$3*S23+Scoring!$H$3*T23)/5*100,0) | V23: =IF(U23>=75,"Tier 1",IF(U23>=65,"Tier 2",IF(U23>=55,"Tier 3","Exclude"))) | W23: Publish now | X23: Covers both sides (business-initiated and client-initiated), refund/UPI wording, short WhatsApp versions, and rescheduling via link. | Y23: The SERP is scattered, with help pages ranking (medfar, findyourally). Setmore support ranks #12 for 'reschedule appointment' (1,000/KD25). | Z23: /features/notifications | AA23: D2, C2, /glossary/reschedule
A24: 23 | B24: Yes | C24: 8 | D24: D1 | E24: D: No-shows, cancellations & booking policies | F24: Pillar | G24: New | H24: How to Reduce No-Shows: A Playbook for Indian Clinics, Coaches, Tutors & Salons | I24: /blog/how-to-reduce-no-shows | J24: how to reduce no shows | K24: Unverified | L24: n/a | M24: how to reduce no shows in clinic, no show appointments, reduce missed appointments, patient no show | N24: Informational | O24: Consideration | P24: 2 | Q24: 3 | R24: 5 | S24: 4 | T24: 4 | U24: =ROUND((Scoring!$D$3*P24+Scoring!$E$3*Q24+Scoring!$F$3*R24+Scoring!$G$3*S24+Scoring!$H$3*T24)/5*100,0) | V24: =IF(U24>=75,"Tier 1",IF(U24>=65,"Tier 2",IF(U24>=55,"Tier 3","Exclude"))) | W24: Publish now | X24: Original data: Book A Sloth no-show rate by reminder type and prepaid vs unpaid. Includes a cost calculator embed, a reminder cadence and policy wording. | Y24: Not fully checked. US SaaS blogs are expected to dominate; this page differentiates on India data. | Z24: /tools/no-show-cost-calculator, /features/notifications | AA24: D2, C1, B2, /tools/no-show-cost-calculator, /glossary/no-show | AB24: Book A Sloth data pull: no-show rates (min sample n≥200 bookings)
A25: 24 | B25: Yes | C25: 8 | D25: G0 | E25: G: Start & grow an independent practice in India (playbooks + pricing guides) | F25: Pillar | G25: New | H25: How to Start an Online Consultation Practice in India (Coaches, Therapists, Tutors, Trainers): Setup, Pricing, Payments & Rules | I25: /blog/start-online-consultation-practice-india | J25: how to start online consultation business | K25: Unverified | L25: n/a | M25: how to start coaching business in india, start online coaching india, how to start consulting business in india, 1:1 coaching business india | N25: Informational | O25: Awareness | P25: 3 | Q25: 4 | R25: 5 | S25: 4 | T25: 4 | U25: =ROUND((Scoring!$D$3*P25+Scoring!$E$3*Q25+Scoring!$F$3*R25+Scoring!$G$3*S25+Scoring!$H$3*T25)/5*100,0) | V25: =IF(U25>=75,"Tier 1",IF(U25>=65,"Tier 2",IF(U25>=55,"Tier 3","Exclude"))) | W25: Publish now | X25: A 1:1 practitioner version of a SERP that reads 'coaching' as tuition institutes. Steps: offer, ₹ pricing, booking page, UPI collection, GST threshold, WhatsApp reminders, policies. Links out to every profession playbook. | Y25: Quora ×2, Reddit ×2, linkedin pulse and registerkaro rank; generic or US-based results. Rated High feasibility. | Z25: /be-a-sloth, /features/booking-pages | AA25: G1, G2, G4, G5, G6, B1, D2 | AB25: Host interviews (2-3 quotes)
A26: 25 | B26: Yes | C26: 8 | D26: C5 | E26: C: Client message templates (WhatsApp, SMS, Hindi) | F26: Support | G26: New | H26: Tuition Fee Reminder Messages for Tutors & Coaching Classes (Hindi + English) | I26: /blog/tuition-fee-reminder-message | J26: tuition fee reminder message | K26: Unverified | L26: n/a | M26: fee reminder message, fee reminder message in hindi, monthly fee reminder for students | N26: Informational | O26: Consideration | P26: 3 | Q26: 5 | R26: 4 | S26: 4 | T26: 3 | U26: =ROUND((Scoring!$D$3*P26+Scoring!$E$3*Q26+Scoring!$F$3*R26+Scoring!$G$3*S26+Scoring!$H$3*T26)/5*100,0) | V26: =IF(U26>=75,"Tier 1",IF(U26>=65,"Tier 2",IF(U26>=55,"Tier 3","Exclude"))) | W26: Publish now | X26: Private tutor and coaching-class angle (the SERP is school-focused): monthly batch fees, UPI QR, parent-friendly Hindi. | Y26: Q&A sites (askfilo, brainly.in) and small Indian sites (fastfee.in, shreetripada) rank. Rated High feasibility. | Z26: /for/tutors | AA26: C4, /for/tutors, G4
A27: 26 | B27: Yes | C27: 9 | D27: G2 | E27: G: Start & grow an independent practice in India (playbooks + pricing guides) | F27: Support | G27: New | H27: How to Start a Private Practice as a Psychologist or Counsellor in India (Operations Guide) | I27: /blog/start-private-practice-psychologist-india | J27: how to start private practice psychologist india | K27: Unverified | L27: n/a | M27: how to start a counselling practice in india, how to get clients as a new psychologist in india, therapist fees in india, do counsellors need shop and establishment licence | N27: Informational | O27: Consideration | P27: 2 | Q27: 4 | R27: 5 | S27: 5 | T27: 4 | U27: =ROUND((Scoring!$D$3*P27+Scoring!$E$3*Q27+Scoring!$F$3*R27+Scoring!$G$3*S27+Scoring!$H$3*T27)/5*100,0) | V27: =IF(U27>=75,"Tier 1",IF(U27>=65,"Tier 2",IF(U27>=55,"Tier 3","Exclude"))) | W27: Publish now | X27: Covers the operations that qualification-focused pages skip: intake forms, confidential booking, fee collection, WhatsApp boundaries, cancellation policy, RCI note. | Y27: Reddit r/Psychology_India ×2, LinkedIn ×2, shoolini, lifehetu. Rated High feasibility. | Z27: /for/therapists | AA27: H5, F3, D2, G1 | AB27: Reviewed by a practising RCI-registered psychologist
A28: 27 | B28: Yes | C28: 9 | D28: H5 | E28: H: Industry booking-software landing pages (/for/*) | F28: Landing | G28: New | H28: Booking & Payments for Psychologists and Therapists in India (Private, Prepaid Sessions) | I28: /for/therapists | J28: therapist booking software india | K28: Unverified | L28: n/a | M28: practice management for therapists india, online counselling booking, psychologist appointment software | N28: Commercial | O28: Conversion | P28: 2 | Q28: 3 | R28: 5 | S28: 4 | T28: 3 | U28: =ROUND((Scoring!$D$3*P28+Scoring!$E$3*Q28+Scoring!$F$3*R28+Scoring!$G$3*S28+Scoring!$H$3*T28)/5*100,0) | V28: =IF(U28>=75,"Tier 1",IF(U28>=65,"Tier 2",IF(U28>=55,"Tier 3","Exclude"))) | W28: Publish now | X28: A core ICP with no /for page today. Covers privacy, intake forms, prepaid sessions, recurring weekly slots and video links. | Y28: Small Indian sites rank (protherapy.in, practipal.in, psychdesk.in, therasoft.in). | Z28: /for/therapists | AA28: F3, D2, G2 | AB28: RCI-registration and privacy copy reviewed
A29: 28 | B29: Yes | C29: 9 | D29: G4 | E29: G: Start & grow an independent practice in India (playbooks + pricing guides) | F29: Support | G29: New | H29: How to Start Online Tuition in India (2026): Fees, Batches, UPI Collection & Parent Reminders | I29: /blog/how-to-start-online-tuition | J29: how to start online tuition | K29: Unverified | L29: n/a | M29: how to start online tuition from home, online tuition business india, online tuition classes setup | N29: Informational | O29: Consideration | P29: 3 | Q29: 4 | R29: 5 | S29: 4 | T29: 3 | U29: =ROUND((Scoring!$D$3*P29+Scoring!$E$3*Q29+Scoring!$F$3*R29+Scoring!$G$3*S29+Scoring!$H$3*T29)/5*100,0) | V29: =IF(U29>=75,"Tier 1",IF(U29>=65,"Tier 2",IF(U29>=55,"Tier 3","Exclude"))) | W29: Publish now | X29: Current results date from 2021-2023. Covers batches, a demo-class booking link, monthly UPI fees, a fee-reminder cadence and parent WhatsApp etiquette. | Y29: YouTube, urbantution, razorpay learn (2021), Quora, mydukaan (2023). Rated High feasibility. | Z29: /for/tutors | AA29: C5, G4b, G4c, H8
A30: 29 | B30: Yes | C30: 10 | D30: G6 | E30: G: Start & grow an independent practice in India (playbooks + pricing guides) | F30: Support | G30: New | H30: How to Price Coaching Services in India (₹ Packages, Retainers & UPI Subscriptions) | I30: /blog/how-to-price-coaching-services-india | J30: how to price coaching services | K30: Unverified | L30: n/a | M30: life coach fees in india, how much do life coaches charge in india, coaching packages pricing, career coach fees india | N30: Informational | O30: Consideration | P30: 2 | Q30: 4 | R30: 5 | S30: 5 | T30: 4 | U30: =ROUND((Scoring!$D$3*P30+Scoring!$E$3*Q30+Scoring!$F$3*R30+Scoring!$G$3*S30+Scoring!$H$3*T30)/5*100,0) | V30: =IF(U30>=75,"Tier 1",IF(U30>=65,"Tier 2",IF(U30>=55,"Tier 3","Exclude"))) | W30: Publish now | X30: Every ranking page quotes USD. Rupee benchmarks, package design and the effective hourly rate after platform fees. | Y30: instituteofcoaching, coactive, paperbell (all US). Rated High feasibility with an India modifier. | Z30: /for/life-coaches | AA30: G1, G7, A11 | AB30: Coach pricing data
A31: 30 | B31: Yes | C31: 10 | D31: L1 | E31: L: Booking-link how-tos (Instagram, Google, website) | F31: Pillar | G31: New | H31: How to Add a Booking Link to Your Instagram Bio (and Get Paid Before the Session) | I31: /blog/booking-link-instagram-bio | J31: booking link for instagram | K31: Unverified | L31: n/a | M31: instagram booking button, how to add book now button on instagram, link in bio for coaches, link in bio that takes payments | N31: Informational | O31: Consideration | P31: 3 | Q31: 4 | R31: 5 | S31: 4 | T31: 3 | U31: =ROUND((Scoring!$D$3*P31+Scoring!$E$3*Q31+Scoring!$F$3*R31+Scoring!$G$3*S31+Scoring!$H$3*T31)/5*100,0) | V31: =IF(U31>=75,"Tier 1",IF(U31>=65,"Tier 2",IF(U31>=55,"Tier 3","Exclude"))) | W31: Publish now | X31: An Indian version with screenshots: bio link, Instagram's 'Book' action button, a WhatsApp handoff and UPI prepay. | Y31: setmore, help.instagram, square, koalendar, linktr.ee, reservio (Jun 2026) and lovingbooking (Jul 2026) rank: small how-to posts. | Z31: /features/booking-pages | AA31: L3, C6, A1 | AB31: Instagram screenshots
A32: 31 | C32: 10 | D32: H1 | E32: H: Industry booking-software landing pages (/for/*) | F32: Landing | G32: Refresh | H32: Turf Booking Software: Online Slot Booking + UPI Advance, 0% Commission | I32: /for/sports-turf | J32: turf booking software | K32: Unverified | L32: n/a | M32: turf booking system, box cricket booking software, turf management software | N32: Commercial | O32: Conversion | P32: 2 | Q32: 5 | R32: 5 | S32: 4 | T32: 2 | U32: =ROUND((Scoring!$D$3*P32+Scoring!$E$3*Q32+Scoring!$F$3*R32+Scoring!$G$3*S32+Scoring!$H$3*T32)/5*100,0) | V32: =IF(U32>=75,"Tier 1",IF(U32>=65,"Tier 2",IF(U32>=55,"Tier 3","Exclude"))) | W32: Publish now | X32: Peak/off-peak pricing, UPI advance, WhatsApp booking link and zero commission vs marketplaces (Playo, Khelomore). | Y32: A very weak SERP: turfbox.in, pitchbooking, sigosoft, a dayschedule forum post and a cyberzio guide (1 Oct 2026). Rated High feasibility. | Z32: /for/sports-turf | AA32: A1, B2 | AB32: Turf owner case study
A33: 32 | C33: 11 | D33: A1 | E33: A: India pricing, alternatives & comparisons | F33: Pillar | G33: New | H33: Best Appointment Booking Apps in India (2026): ₹ Pricing, UPI & WhatsApp Compared | I33: /compare/best-appointment-booking-apps-india | J33: appointment scheduling app india | K33: Unverified | L33: n/a | M33: free appointment booking app india, appointment booking app india, best scheduling app india | N33: Commercial | O33: Consideration | P33: 3 | Q33: 3 | R33: 5 | S33: 4 | T33: 5 | U33: =ROUND((Scoring!$D$3*P33+Scoring!$E$3*Q33+Scoring!$F$3*R33+Scoring!$G$3*S33+Scoring!$H$3*T33)/5*100,0) | V33: =IF(U33>=75,"Tier 1",IF(U33>=65,"Tier 2",IF(U33>=55,"Tier 3","Exclude"))) | W33: Publish now | X33: An honest list that includes competitors (Zoho, Calendly, Topmate, Setmore, Cal.com, Picktime, Appointy, Book A Sloth). One table: ₹ monthly cost incl. 18% GST, UPI support, WhatsApp reminders, commission, GST invoice. Methodology box plus a 'last tested' date. | Y33: A US Square page is #1 for 'free appointment booking app india'. zapier, simplybook and zoho also rank. No result shows ₹ pricing or UPI support. | Z33: /pricing, /features/payments | AA33: A2, A3, A5, B1, C13, /pricing | AB33: A fresh test account on each tool; screenshots; a ₹ conversion with the date; a pricing-check log
A34: 33 | C34: 11 | D34: G8 | E34: G: Start & grow an independent practice in India (playbooks + pricing guides) | F34: Support | G34: New | H34: Doctor Consultation Fees in India: How to Set Yours (Specialty, City, Follow-Up Rules) | I34: /blog/doctor-consultation-fee-india | J34: consultation fee for doctors in india | K34: Unverified | L34: n/a | M34: how much should a new doctor charge for consultation, follow up consultation fee rules, online consultation fee for doctors | N34: Informational | O34: Consideration | P34: 3 | Q34: 4 | R34: 4 | S34: 4 | T34: 4 | U34: =ROUND((Scoring!$D$3*P34+Scoring!$E$3*Q34+Scoring!$F$3*R34+Scoring!$G$3*S34+Scoring!$H$3*T34)/5*100,0) | V34: =IF(U34>=75,"Tier 1",IF(U34>=65,"Tier 2",IF(U34>=55,"Tier 3","Exclude"))) | W34: Publish now | X34: Written for the doctor. Covers specialty × city ranges, follow-up norms and online vs in-clinic. Sources needed: NMC telemedicine guidelines. | Y34: Dominated by UGC: Facebook ×2, Reddit ×2, Quora. Only coveryou targets doctors. Rated High feasibility. | Z34: /for/doctors | AA34: H7, G1, D1 | AB34: Doctor reviewer; NMC sources
A35: 34 | C35: 11 | D35: H7 | E35: H: Industry booking-software landing pages (/for/*) | F35: Landing | G35: Consolidate | H35: Clinic Appointment Booking Software for India (Doctors, Solo Clinics) | I35: /for/doctors | J35: clinic appointment booking software india | K35: Unverified | L35: n/a | M35: appointment booking app for doctors, doctor appointment system, free doctor appointment booking software, doctor appointment app | N35: Commercial | O35: Conversion | P35: 3 | Q35: 3 | R35: 5 | S35: 3 | T35: 2 | U35: =ROUND((Scoring!$D$3*P35+Scoring!$E$3*Q35+Scoring!$F$3*R35+Scoring!$G$3*S35+Scoring!$H$3*T35)/5*100,0) | V35: =IF(U35>=75,"Tier 1",IF(U35>=65,"Tier 2",IF(U35>=55,"Tier 3","Exclude"))) | W35: Publish now | X35: 301 /for/doctors-india into /for/doctors. Honest positioning: booking, payments and reminders, not EMR. Include ₹ pricing. | Y35: zoho, docpulse, appointik.in, shmsolutions.in, doctorsapp.in and treatlly (25 Sep 2026) rank. Several small Indian sites. | Z35: /for/doctors | AA35: C1, D1, D2
A36: 35 | C36: 12 | D36: C12 | E36: C: Client message templates (WhatsApp, SMS, Hindi) | F36: Support | G36: New | H36: पेमेंट रिमाइंडर मैसेज (Payment Reminder Message in Hindi): WhatsApp Templates | I36: /blog/payment-reminder-message-hindi | J36: payment reminder message in hindi | K36: Unverified | L36: n/a | M36: payment reminder in hindi, paisa reminder message, udhaar reminder message | N36: Informational | O36: Consideration | P36: 2 | Q36: 5 | R36: 4 | S36: 5 | T36: 2 | U36: =ROUND((Scoring!$D$3*P36+Scoring!$E$3*Q36+Scoring!$F$3*R36+Scoring!$G$3*S36+Scoring!$H$3*T36)/5*100,0) | V36: =IF(U36>=75,"Tier 1",IF(U36>=65,"Tier 2",IF(U36>=55,"Tier 3","Exclude"))) | W36: Publish now | X36: Hindi-first page that links to C4. Covers shopkeeper and service-business variants. | Y36: 6 of 10 results are translate.google proxies. Rated High feasibility. | Z36: /features/payments | AA36: C4, C5 | AB36: Native Hindi writer
A37: 36 | C37: 12 | D37: C2 | E37: C: Client message templates (WhatsApp, SMS, Hindi) | F37: Support | G37: New | H37: Appointment Confirmation Message Templates (WhatsApp, SMS & Email with Payment Receipt) | I37: /blog/appointment-confirmation-message | J37: appointment confirmation message | K37: Unverified | L37: n/a | M37: booking confirmation message, appointment confirmation whatsapp message, consultation booking confirmation | N37: Informational | O37: Consideration | P37: 3 | Q37: 3 | R37: 5 | S37: 4 | T37: 3 | U37: =ROUND((Scoring!$D$3*P37+Scoring!$E$3*Q37+Scoring!$F$3*R37+Scoring!$G$3*S37+Scoring!$H$3*T37)/5*100,0) | V37: =IF(U37>=75,"Tier 1",IF(U37>=65,"Tier 2",IF(U37>=55,"Tier 3","Exclude"))) | W37: Publish now | X37: Service-business confirmations (not hotel/travel) that include the prepaid UPI receipt line, location or meeting link, and the cancellation-policy line. | Y37: formalert.in (small Indian site) is #7. The booking-confirmation SERP is hotel/travel-heavy (xola, mews). | Z37: /features/notifications | AA37: C1, C3, D2 | AB37: Screenshots of the Book A Sloth confirmation message
A38: 37 | C38: 12 | D38: F3 | E38: F: Scheduling concepts & glossary | F38: Template | G38: New | H38: Client Intake Form Questions for Coaches, Therapists & Consultants (Copy-Ready Templates) | I38: /templates/client-intake-form | J38: client intake form questions | K38: Unverified | L38: n/a | M38: intake form template, coaching intake form, therapy intake form questions, consultation form questions | N38: Informational | O38: Consideration | P38: 2 | Q38: 3 | R38: 5 | S38: 4 | T38: 4 | U38: =ROUND((Scoring!$D$3*P38+Scoring!$E$3*Q38+Scoring!$F$3*R38+Scoring!$G$3*S38+Scoring!$H$3*T38)/5*100,0) | V38: =IF(U38>=75,"Tier 1",IF(U38>=65,"Tier 2",IF(U38>=55,"Tier 3","Exclude"))) | W38: Publish now | X38: Question banks by profession, with a privacy note (DPDP Act basics) and a link to the booking-page intake feature. | Y38: Not checked. | Z38: /features/booking-pages | AA38: F2, C7, /glossary/intake-form | AB38: DPDP Act reference
A39: 38 | C39: 13 | D39: G5 | E39: G: Start & grow an independent practice in India (playbooks + pricing guides) | F39: Support | G39: New | H39: How to Start Online Yoga Classes in India: Batches, Pricing, UPI & Zoom Setup | I39: /blog/how-to-start-online-yoga-classes | J39: how to start yoga classes online | K39: Unverified | L39: n/a | M39: online yoga classes business, how much to charge for online yoga class india, yoga teacher income india | N39: Informational | O39: Consideration | P39: 2 | Q39: 4 | R39: 5 | S39: 4 | T39: 3 | U39: =ROUND((Scoring!$D$3*P39+Scoring!$E$3*Q39+Scoring!$F$3*R39+Scoring!$G$3*S39+Scoring!$H$3*T39)/5*100,0) | V39: =IF(U39>=75,"Tier 1",IF(U39>=65,"Tier 2",IF(U39>=55,"Tier 3","Exclude"))) | W39: Publish now | X39: Results are mostly non-India or about equipment. Covers India pricing, monthly UPI batches and Zoom links over WhatsApp. | Y39: sevensundaysyoga, sampoornayoga, YouTube ×3, Reddit. Rated High feasibility. | Z39: /for/yoga-instructors | AA39: H6, G1, C5
A40: 39 | C40: 13 | D40: H6 | E40: H: Industry booking-software landing pages (/for/*) | F40: Landing | G40: New | H40: Yoga Class Booking: Batches, Monthly UPI Fees & WhatsApp Reminders | I40: /for/yoga-instructors | J40: yoga class booking app | K40: Unverified | L40: n/a | M40: yoga studio booking software, online yoga class booking | N40: Commercial | O40: Conversion | P40: 2 | Q40: 3 | R40: 5 | S40: 4 | T40: 2 | U40: =ROUND((Scoring!$D$3*P40+Scoring!$E$3*Q40+Scoring!$F$3*R40+Scoring!$G$3*S40+Scoring!$H$3*T40)/5*100,0) | V40: =IF(U40>=75,"Tier 1",IF(U40>=65,"Tier 2",IF(U40>=55,"Tier 3","Exclude"))) | W40: Publish now | X40: Nothing India-specific ranks. Covers monthly batches, UPI and Instagram/WhatsApp. | Y40: lunacal, Momoyoga and yogobooking rank (global small SaaS). | Z40: /for/yoga-instructors | AA40: G5, C5
...

Sheet Keyword Database
A1: Keyword | B1: Role | C1: Page primary keyword | D1: Supporting keywords (for primary rows) | E1: India volume | F1: Volume source & date | G1: KD | H1: KD source | I1: Search intent | J1: SERP competition (observed 2026-10-10) | K1: Competitor positions (export) | L1: Ranking opportunity / angle | M1: Business relevance | N1: Funnel stage | O1: AI citation potential | P1: AI rationale | Q1: Content type | R1: Priority score | S1: Tier | T1: Recommended URL | U1: Article ID | V1: Cluster | W1: Action | X1: Semrush SERP features
A2: appointment scheduling app india | B2: Primary | C2: appointment scheduling app india | D2: free appointment booking app india, appointment booking app india, best scheduling app india | E2: Unverified | F2: Unverified: validate in Semrush India / Google Keyword Planner | G2: n/a | H2: n/a | I2: Commercial | J2: A US Square page is #1 for 'free appointment booking app india'. zapier, simplybook and zoho also rank. No result shows ₹ pricing or UPI support. | L2: An honest list that includes competitors (Zoho, Calendly, Topmate, Setmore, Cal.com, Picktime, Appointy, Book A Sloth). One table: ₹ monthly cost incl. 18% GST, UPI support, WhatsApp reminders, commission, GST invoice. Methodology box plus a 'last tested' date. | M2: High | N2: Consideration | O2: High | P2: Pricing and comparison facts in ₹ that no current source gives | Q2: Pillar guide | R2: 77 | S2: Tier 1 | T2: /compare/best-appointment-booking-apps-india | U2: A1 | V2: A: India pricing, alternatives & comparisons | W2: New
A3: online booking website | B3: Supporting (from competitor data) | C3: appointment scheduling app india | E3: 390 | F3: Semrush India DB via competitor Organic Positions exports (calendly.com 2026-09-10, topmate.io 2026-09-10, setmore.com 2026-09-11) | G3: 40 | H3: Semrush | I3: informational | J3: A US Square page is #1 for 'free appointment booking app india'. zapier, simplybook and zoho also rank. No result shows ₹ pricing or UPI support. | K3: calendly #12; setmore #4 | L3: An honest list that includes competitors (Zoho, Calendly, Topmate, Setmore, Cal.com, Picktime, Appointy, Book A Sloth). One table: ₹ monthly cost incl. 18% GST, UPI support, WhatsApp reminders, commission, GST invoice. Methodology box plus a 'last tested' date. | M3: High | N3: Consideration | O3: High | P3: Pricing and comparison facts in ₹ that no current source gives | Q3: Pillar guide | R3: 77 | S3: Tier 1 | T3: /compare/best-appointment-booking-apps-india | U3: A1 | V3: A: India pricing, alternatives & comparisons | W3: New | X3: Sitelinks, Reviews, Video, People also ask, Related searches, AI overview
A4: schedule service | B4: Supporting (from competitor data) | C4: appointment scheduling app india | E4: 320 | F4: Semrush India DB via competitor Organic Positions exports (calendly.com 2026-09-10, topmate.io 2026-09-10, setmore.com 2026-09-11) | G4: 30 | H4: Semrush | I4: informational | J4: A US Square page is #1 for 'free appointment booking app india'. zapier, simplybook and zoho also rank. No result shows ₹ pricing or UPI support. | K4: setmore #39 | L4: An honest list that includes competitors (Zoho, Calendly, Topmate, Setmore, Cal.com, Picktime, Appointy, Book A Sloth). One table: ₹ monthly cost incl. 18% GST, UPI support, WhatsApp reminders, commission, GST invoice. Methodology box plus a 'last tested' date. | M4: High | N4: Consideration | O4: High | P4: Pricing and comparison facts in ₹ that no current source gives | Q4: Pillar guide | R4: 77 | S4: Tier 1 | T4: /compare/best-appointment-booking-apps-india | U4: A1 | V4: A: India pricing, alternatives & comparisons | W4: New | X4: Reviews, Video, People also ask, Related searches, AI overview
A5: service scheduling software | B5: Supporting (from competitor data) | C5: appointment scheduling app india | E5: 320 | F5: Semrush India DB via competitor Organic Positions exports (calendly.com 2026-09-10, topmate.io 2026-09-10, setmore.com 2026-09-11) | G5: 30 | H5: Semrush | I5: commercial | J5: A US Square page is #1 for 'free appointment booking app india'. zapier, simplybook and zoho also rank. No result shows ₹ pricing or UPI support. | K5: setmore #24 | L5: An honest list that includes competitors (Zoho, Calendly, Topmate, Setmore, Cal.com, Picktime, Appointy, Book A Sloth). One table: ₹ monthly cost incl. 18% GST, UPI support, WhatsApp reminders, commission, GST invoice. Methodology box plus a 'last tested' date. | M5: High | N5: Consideration | O5: High | P5: Pricing and comparison facts in ₹ that no current source gives | Q5: Pillar guide | R5: 77 | S5: Tier 1 | T5: /compare/best-appointment-booking-apps-india | U5: A1 | V5: A: India pricing, alternatives & comparisons | W5: New | X5: Sitelinks, Reviews, Video, Related searches, AI overview
